<?xml version="1.6"?>

<robot xmlns:xacro="http://www.ros.org/wiki/xacro" name="barista">

    <xacro:property name="robot_name" value="$(arg robot_name)"/>

    <xacro:include filename="$(find barista_robot_description)/xacro/wheel.xacro"/>
    <xacro:include filename="$(find barista_robot_description)/xacro/standoff.xacro"/>
    <xacro:include filename="$(find barista_robot_description)/xacro/cup_holder_tray.xacro"/>

    <material name="blue">
        <color rgba="0.0 0.0 1.0 1.0"/>
    </material>

    <material name="light_gray">
        <color rgba="0.83 0.83 0.83 1.0"/>
    </material>

    <material name="black">
        <color rgba="0.0 0.0 0.0 1.0"/>
    </material>

    <!-- Robot base/root link -->
    <link name="base_footprint"/>

    <link name="chassis">
        <visual>
            <origin rpy="0 0 0" xyz="0 0 0"/>
            <geometry>
                <cylinder length="0.155" radius="0.178"/>
            </geometry>
            <material name="blue"/>
        </visual>
                        
        <collision>
            <origin rpy="0 0 0" xyz="0 0 0"/>
            <geometry>
                <cylinder length="0.155" radius="0.178"/>
            </geometry>
        </collision>

        <inertial>
            <mass value="5.0"/>
            <origin rpy="0 0 0" xyz="0 0 0"/>
            <inertia ixx="0.04961541666666667" ixy="0.0" ixz="0.0" iyy="0.04961541666666667" iyz="0.0" izz="0.07920999999999999"/>
        </inertial>
    </link>

    <gazebo reference="chassis">
        <material>Gazebo/Blue</material>
    </gazebo>

    <joint name="joint_base_footprint_chassis" type="fixed">
        <origin rpy="0 0 0" xyz="0 0 0"/>
        <parent link="base_footprint"/>
        <child link="chassis"/>
        <axis xyz="0 0 0"/>
    </joint>

    <link name="standoff_rods">
        <xacro:standoff x_coord="0.050" y_coord="0.140"/>
        <xacro:standoff x_coord="-0.050" y_coord="0.140"/>
        <xacro:standoff x_coord="0.050" y_coord="-0.140"/>
        <xacro:standoff x_coord="-0.050" y_coord="-0.140"/>

        <!-- approximate a very light box with size [0.1, 0.28, 0.22] -->
        <inertial>
            <mass value="0.4"/>
            <origin rpy="0 0 0" xyz="0 0 0"/>
            <inertia ixx="0.004226666666666668" ixy="0.0" ixz="0.0" iyy="0.0019466666666666666" iyz="0.0" izz="0.002946666666666667"/>
        </inertial>

    </link>

    <joint name="joint_chassis_standoff_rods" type="fixed">
        <origin rpy="0 0 0" xyz="0 0 0.1875"/>
        <parent link="chassis"/>
        <child link="standoff_rods"/>
        <axis xyz="0 0 0"/>
    </joint>

    <xacro:cup_holder_tray/>

    <gazebo reference="cup_holder">
        <material>Gazebo/Blue</material>
    </gazebo>

    <joint name="joint_standoff_rods_cup_holder" type="fixed">
        <origin rpy="0 0 0" xyz="0 0 0.155"/>
        <parent link="standoff_rods"/>
        <child link="cup_holder"/>
        <axis xyz="0 0 0"/>
    </joint>

  <!-- Wheels -->
  <!-- Wheel Left -->
  <xacro:wheel wheel_name="left_wheel"/>

  <gazebo reference="left_wheel">
    <kp>1000000000000000000000000000.0</kp>
    <kd>1000000000000000000000000000.0</kd>
    <mu1>10.0</mu1>
    <mu2>10.0</mu2>
    <material>Gazebo/Black</material>
  </gazebo>


  <joint name="joint_chassis_left_wheel" type="continuous">
    <origin rpy="0 0 0" xyz="0 0.145 -0.07"/> <!-- axis flush with base at -0.0775 -->
    <parent link="chassis"/>
    <child link="left_wheel"/>
    <axis rpy="0 0 0" xyz="0 1 0"/>
    <limit effort="10000" velocity="1000"/>
    <joint_properties damping="1.0" friction="1.0"/>
  </joint>

  <!-- Wheel right -->
  <xacro:wheel wheel_name="right_wheel"/>

  <gazebo reference="right_wheel">
    <kp>1000000000000000000000000000.0</kp>
    <kd>1000000000000000000000000000.0</kd>
    <mu1>10.0</mu1>
    <mu2>10.0</mu2>
    <material>Gazebo/Black</material>
  </gazebo>


  <joint name="joint_chassis_right_wheel" type="continuous">
    <origin rpy="0 0 0" xyz="0 -0.145 -0.07"/> <!-- axis flush with base at -0.0775 -->
    <parent link="chassis"/>
    <child link="right_wheel"/>
    <axis rpy="0 0 0" xyz="0 1 0"/>
    <limit effort="10000" velocity="1000"/>
    <joint_properties damping="1.0" friction="1.0"/>
  </joint>

    <!-- Casters -->
  <!-- Caster Wheel Front -->
  <link name="front_yaw_link">
      <visual>
        <origin rpy="0 1.5707 1.5707" xyz="0 0 0"/>
        <geometry>          
          <cylinder length="0.001" radius="0.0045000000000000005"/>
        </geometry>
        <material name="black"/>
      </visual>

      <collision>
        <origin rpy="0 1.5707 1.5707" xyz="0 0 0"/>
        <geometry>
          <cylinder length="0.001" radius="0.0045000000000000005"/>
        </geometry>
      </collision>

      <inertial>
          <origin rpy="0 1.5707 1.5707" xyz="0 0 0"/>
          <mass value="0.001"/>
          <inertia ixx="5.145833333333334e-09" ixy="0" ixz="0" iyy="5.145833333333334e-09" iyz="0" izz="1.0125000000000003e-08"/>
      </inertial>

  </link>

  <joint name="front_yaw_joint" type="continuous">
    <origin rpy="0 0 0" xyz="0.13 0 -0.0775" />
    <parent link="chassis" />
    <child link="front_yaw_link" />
    <axis xyz="0 0 1" />
    <limit effort="1000.0" velocity="100.0" />
    <dynamics damping="0.0" friction="0.1"/>
  </joint>

    <gazebo reference="front_yaw_link">
        <material>Gazebo/Black</material>
    </gazebo>

  <link name="front_roll_link">
      <visual>
        <origin rpy="0 1.5707 1.5707" xyz="0 0 0"/>
        <geometry>
          <cylinder length="0.001" radius="0.0045000000000000005"/>
        </geometry>
        <material name="black"/>
      </visual>

      <collision>
        <origin rpy="0 1.5707 1.5707" xyz="0 0 0"/>
        <geometry>
          <cylinder length="0.001" radius="0.0045000000000000005"/>
        </geometry>
      </collision>

      <inertial>
          <origin rpy="0 1.5707 1.5707" xyz="0 0 0"/>
          <mass value="0.001"/>
          <inertia ixx="5.145833333333334e-09" ixy="0" ixz="0" iyy="5.145833333333334e-09" iyz="0" izz="1.0125000000000003e-08"/>
      </inertial>
  </link>

  <joint name="front_roll_joint" type="continuous">
    <origin rpy="0 0 0" xyz="0 0 0" />
    <parent link="front_yaw_link" />
    <child link="front_roll_link" />
    <axis xyz="1 0 0" />
    <limit effort="1000.0" velocity="100.0" />
    <dynamics damping="0.0" friction="0.1"/>
  </joint>

    <gazebo reference="front_roll_link">
        <material>Gazebo/Black</material>
    </gazebo>


  <link name="front_pitch_link">
    <visual>
      <origin rpy="0 1.5707 1.5707" xyz="0 0 0"/>
      <geometry>
        <sphere radius="0.0277"/>
      </geometry>
      <material name="black"/>
    </visual>

    <collision>
      <origin rpy="0 1.5707 1.5707" xyz="0 0 0"/>
      <geometry>
        <sphere radius="0.0277"/>
      </geometry>
    </collision>

    <inertial>
        <origin rpy="0 1.5707 1.5707" xyz="0 0 0"/>
        <mass value="0.06"/>
        <inertia ixx="1.8414959999999996e-05" ixy="0.0" ixz="0.0" iyy="1.8414959999999996e-05" iyz="0.0" izz="1.8414959999999996e-05"/>
    </inertial>
  </link>

  <gazebo reference="front_pitch_link">
    <kp>1000000000000000000000000000.0</kp>
    <kd>1000000000000000000000000000.0</kd>
    <mu1>0.5</mu1>
    <mu2>0.5</mu2>
    <material>Gazebo/Black</material>
  </gazebo>

  <joint name="front_pitch_joint" type="continuous">
    <origin rpy="0 0 0" xyz="0 0 0" />
    <parent link="front_roll_link" />
    <child link="front_pitch_link" />
    <axis xyz="0 1 0" />
    <limit effort="1000.0" velocity="100.0" />
    <dynamics damping="0.0" friction="0.1"/>
  </joint>

   <!-- Caster Wheel Back -->
  <link name="back_yaw_link">
      <visual>
        <origin rpy="0 1.5707 1.5707" xyz="0 0 0"/>
        <geometry>          
          <cylinder length="0.001" radius="0.0045000000000000005"/>
        </geometry>
        <material name="black"/>
      </visual>

      <collision>
        <origin rpy="0 1.5707 1.5707" xyz="0 0 0"/>
        <geometry>
          <cylinder length="0.001" radius="0.0045000000000000005"/>
        </geometry>
      </collision>

      <inertial>
          <origin rpy="0 1.5707 1.5707" xyz="0 0 0"/>
          <mass value="0.001"/>
          <inertia ixx="5.145833333333334e-09" ixy="0" ixz="0" iyy="5.145833333333334e-09" iyz="0" izz="1.0125000000000003e-08"/>
      </inertial>

  </link>

  <joint name="back_yaw_joint" type="continuous">
    <origin rpy="0 0 0" xyz="-0.13 0 -0.0775" />
    <parent link="chassis" />
    <child link="back_yaw_link" />
    <axis xyz="0 0 1" />
    <limit effort="1000.0" velocity="100.0" />
    <dynamics damping="0.0" friction="0.1"/>
  </joint>

    <gazebo reference="back_yaw_link">
        <material>Gazebo/Black</material>
    </gazebo>

  <link name="back_roll_link">
      <visual>
        <origin rpy="0 1.5707 1.5707" xyz="0 0 0"/>
        <geometry>
          <cylinder length="0.001" radius="0.0045000000000000005"/>
        </geometry>
        <material name="black"/>
      </visual>

      <collision>
        <origin rpy="0 1.5707 1.5707" xyz="0 0 0"/>
        <geometry>
          <cylinder length="0.001" radius="0.0045000000000000005"/>
        </geometry>
      </collision>

      <inertial>
          <origin rpy="0 1.5707 1.5707" xyz="0 0 0"/>
          <mass value="0.001"/>
          <inertia ixx="5.145833333333334e-09" ixy="0" ixz="0" iyy="5.145833333333334e-09" iyz="0" izz="1.0125000000000003e-08"/>
      </inertial>
  </link>

  <joint name="back_roll_joint" type="continuous">
    <origin rpy="0 0 0" xyz="0 0 0" />
    <parent link="back_yaw_link" />
    <child link="back_roll_link" />
    <axis xyz="1 0 0" />
    <limit effort="1000.0" velocity="100.0" />
    <dynamics damping="0.0" friction="0.1"/>
  </joint>

    <gazebo reference="back_roll_link">
        <material>Gazebo/Black</material>
    </gazebo>


  <link name="back_pitch_link">
    <visual>
      <origin rpy="0 1.5707 1.5707" xyz="0 0 0"/>
      <geometry>
        <sphere radius="0.0277"/>
      </geometry>
      <material name="black"/>
    </visual>

    <collision>
      <origin rpy="0 1.5707 1.5707" xyz="0 0 0"/>
      <geometry>
        <sphere radius="0.0277"/>
      </geometry>
    </collision>

    <inertial>
        <origin rpy="0 1.5707 1.5707" xyz="0 0 0"/>
        <mass value="0.06"/>
        <inertia ixx="1.8414959999999996e-05" ixy="0.0" ixz="0.0" iyy="1.8414959999999996e-05" iyz="0.0" izz="1.8414959999999996e-05"/>
    </inertial>
  </link>

  <gazebo reference="back_pitch_link">
    <kp>1000000000000000000000000000.0</kp>
    <kd>1000000000000000000000000000.0</kd>
    <mu1>0.5</mu1>
    <mu2>0.5</mu2>
    <material>Gazebo/Black</material>
  </gazebo>

  <joint name="back_pitch_joint" type="continuous">
    <origin rpy="0 0 0" xyz="0 0 0" />
    <parent link="back_roll_link" />
    <child link="back_pitch_link" />
    <axis xyz="0 1 0" />
    <limit effort="1000.0" velocity="100.0" />
    <dynamics damping="0.0" friction="0.1"/>
  </joint>

   <!-- Plugins -->
   <!-- Joint publisher (for Gazebo)-->
  <gazebo>
    <plugin name="bar_bot_joint_state" filename="libgazebo_ros_joint_state_publisher.so">
      <ros>
          <namespace>/${robot_name}</namespace>
          <remapping>~/out:=joint_states</remapping>
      </ros>
      <update_rate>30</update_rate>

      <joint_name>joint_chassis_left_wheel</joint_name>
      <joint_name>joint_chassis_right_wheel</joint_name>
      <joint_name>front_yaw_joint</joint_name>
      <joint_name>back_yaw_joint</joint_name>
      <joint_name>front_roll_joint</joint_name>
      <joint_name>back_roll_joint</joint_name>
      <joint_name>front_pitch_joint</joint_name>
      <joint_name>back_pitch_joint</joint_name>
      
    </plugin>
  </gazebo>

   <!-- Differential driver -->
   <gazebo>
    <plugin filename="libgazebo_ros_diff_drive.so" name="differential_drive_controller">

      <!-- namespace for multiple robots from the same model-->
      <ros>
        <namespace>/${robot_name}</namespace>
        <remapping>/cmd_vel:=cmd_vel</remapping>
      </ros>

      <!-- wheels -->
      <left_joint>joint_chassis_left_wheel</left_joint>
      <right_joint>joint_chassis_right_wheel</right_joint>

      <!-- kinematics -->
      <wheel_separation>0.3106</wheel_separation>
      <wheel_diameter>0.0704</wheel_diameter>

      <!-- limits -->
      <max_wheel_torque>1.0</max_wheel_torque>
      <max_wheel_acceleration>2.0</max_wheel_acceleration>

      <!-- output -->
      <publish_odom>true</publish_odom>
      <publish_odom_tf>true</publish_odom_tf>

      <odometry_frame>${robot_name}/odom</odometry_frame>
      <robot_base_frame>${robot_name}/base_footprint</robot_base_frame>

    </plugin>
  </gazebo>
  
 
  <!-- Laser scanner (conditional) -->
    <xacro:arg name="include_laser" default="true"/>

    <xacro:if value="$(arg include_laser)">
        <xacro:include filename="$(find barista_robot_description)/xacro/laser_scanner.xacro"/>
        <xacro:laser_scanner/>
    </xacro:if>

</robot>