<?xml version="1.6"?>

<robot name="barista">
    <material name="blue">
        <color rgba="0.0 0.0 1.0 1.0"/>
    </material>

    <material name="light_gray">
        <color rgba="0.83 0.83 0.83 1.0"/>
    </material>

    <material name="black">
        <color rgba="0.0 0.0 0.0 1.0"/>
    </material>

    <link name="base_footprint"/>

    <link name="base_link">
        <visual>
            <origin rpy="0 0 0" xyz="0 0 0"/>
            <geometry>
                <cylinder length="0.155" radius="0.178"/>
            </geometry>
            <material name="blue"/>
        </visual>
                        
        <collision>
            <origin rpy="0 0 0" xyz="0 0 0"/>
            <geometry>
                <cylinder length="0.155" radius="0.178"/>
            </geometry>
        </collision>

        <inertial>
            <mass value="1.0"/>
            <origin rpy="0 0 0" xyz="0 0 0"/>
            <inertia ixx="0.009923083333333332" ixy="0.0" ixz="0.0" iyy="0.009923083333333332" iyz="0.0" izz="0.015842"/>
        </inertial>
    </link>

    <gazebo reference="base_link">
        <material>Gazebo/Blue</material>
    </gazebo>

    <joint name="joint_base_footprint_base_link" type="fixed">
        <origin rpy="0 0 0" xyz="0 0 0"/>
        <parent link="base_footprint"/>
        <child link="base_link"/>
        <axis xyz="0 0 0"/>
    </joint>

    <link name="standoff_rods">
        <visual>
            <origin rpy="0 0 0" xyz="0.050 0.140 0"/>
            <geometry>
                <cylinder length="0.220" radius="0.010"/>
            </geometry>
            <material name="light_gray"/>
        </visual>

        <visual>
            <origin rpy="0 0 0" xyz="-0.050 0.140 0"/>
            <geometry>
                <cylinder length="0.220" radius="0.010"/>
            </geometry>
            <material name="light_gray"/>
        </visual>

        <visual>
            <origin rpy="0 0 0" xyz="0.050 -0.140 0"/>
            <geometry>
                <cylinder length="0.220" radius="0.010"/>
            </geometry>
            <material name="light_gray"/>
        </visual>

        <visual>
            <origin rpy="0 0 0" xyz="-0.050 -0.140 0"/>
            <geometry>
                <cylinder length="0.220" radius="0.010"/>
            </geometry>
            <material name="light_gray"/>
        </visual>

        <!-- collision -->
        <collision>
            <origin rpy="0 0 0" xyz="0.050 0.140 0"/>
            <geometry>
                <cylinder length="0.220" radius="0.010"/>
            </geometry>
        </collision>

        <collision>
            <origin rpy="0 0 0" xyz="-0.050 0.140 0"/>
            <geometry>
                <cylinder length="0.220" radius="0.010"/>
            </geometry>
        </collision>

        <collision>
            <origin rpy="0 0 0" xyz="0.050 -0.140 0"/>
            <geometry>
                <cylinder length="0.220" radius="0.010"/>
            </geometry>
        </collision>

        <collision>
            <origin rpy="0 0 0" xyz="-0.050 -0.140 0"/>
            <geometry>
                <cylinder length="0.220" radius="0.010"/>
            </geometry>
            <material name="light_gray"/>
        </collision>

        <!-- approximate a very light box with rods on the edges -->
        <inertial>
            <mass value="0.02"/>
            <origin rpy="0 0 0" xyz="0 0 0"/>
            <inertia ixx="0.0002113333333333334" ixy="0.0" ixz="0.0" iyy="9.733333333333335e-05" iyz="0.0" izz="0.00014733333333333335"/>
        </inertial>

    </link>

    <joint name="joint_base_link_standoff_rods" type="fixed">
        <origin rpy="0 0 0" xyz="0 0 0.1875"/>
        <parent link="base_link"/>
        <child link="standoff_rods"/>
        <axis xyz="0 0 0"/>
    </joint>

    <link name="cup_holder">
        <visual>
            <origin rpy="0 0 0" xyz="0 0 0"/>
            <geometry>
                <cylinder length="0.090" radius="0.160"/>
            </geometry>
            <material name="blue"/>
        </visual>
                        
        <collision>
            <origin rpy="0 0 0" xyz="0 0 0"/>
            <geometry>
                <cylinder length="0.090" radius="0.160"/>
            </geometry>
        </collision>

        <inertial>
            <mass value="0.2"/>
            <origin rpy="0 0 0" xyz="0 0 0"/>
            <inertia ixx="0.001415" ixy="0.0" ixz="0.0" iyy="0.001415" iyz="0.0" izz="0.00256"/>
        </inertial>
    </link>

    <gazebo reference="cup_holder">
        <material>Gazebo/Blue</material>
    </gazebo>

    <joint name="joint_standoff_rods_cup_holder" type="fixed">
        <origin rpy="0 0 0" xyz="0 0 0.155"/>
        <parent link="standoff_rods"/>
        <child link="cup_holder"/>
        <axis xyz="0 0 0"/>
    </joint>

    <!-- Wheels -->
  <!-- Wheel Left -->
  <link name="left_wheel">      
      <visual>
        <origin rpy="0 1.5707 1.5707" xyz="0 0 0"/>
        <geometry>
          <cylinder length="0.025" radius="0.04"/>
        </geometry>
        <material name="black"/>
      </visual>

      <collision>
        <origin rpy="0 1.5707 1.5707" xyz="0 0 0"/>
        <geometry>
          <cylinder length="0.025" radius="0.04"/>
        </geometry>
      </collision>

      <inertial>
        <origin rpy="0 1.5707 1.5707" xyz="0 0 0"/>
        <mass value="0.05"/>
        <inertia ixx="1.531666666666667e-05" ixy="0" ixz="0" iyy="1.531666666666667e-05" iyz="0" izz="3.0625000000000006e-05"/>
      </inertial>

  </link>

  <gazebo reference="left_wheel">
    <kp>1000000000000000000000000000.0</kp>
    <kd>1000000000000000000000000000.0</kd>
    <mu1>10.0</mu1>
    <mu2>10.0</mu2>
    <material>Gazebo/Black</material>
  </gazebo>


  <joint name="joint_base_link_left_wheel" type="continuous">
    <origin rpy="0 0 0" xyz="0 0.145 -0.07"/> <!-- axis flush with base at -0.0775 -->
    <parent link="base_link"/>
    <child link="left_wheel"/>
    <axis rpy="0 0 0" xyz="0 1 0"/>
    <limit effort="10000" velocity="1000"/>
    <joint_properties damping="1.0" friction="1.0"/>
  </joint>

  <!-- Wheel right -->
  <link name="right_wheel">      
      <visual>
        <origin rpy="0 1.5707 1.5707" xyz="0 0 0"/>
        <geometry>
          <cylinder length="0.025" radius="0.04"/>
        </geometry>
        <material name="black"/>
      </visual>

      <collision>
        <origin rpy="0 1.5707 1.5707" xyz="0 0 0"/>
        <geometry>
          <cylinder length="0.025" radius="0.04"/>
        </geometry>
      </collision>

      <inertial>
        <origin rpy="0 1.5707 1.5707" xyz="0 0 0"/>
        <mass value="0.05"/>
        <inertia ixx="1.531666666666667e-05" ixy="0" ixz="0" iyy="1.531666666666667e-05" iyz="0" izz="3.0625000000000006e-05"/>
      </inertial>

  </link>

  <gazebo reference="left_wheel">
    <kp>1000000000000000000000000000.0</kp>
    <kd>1000000000000000000000000000.0</kd>
    <mu1>10.0</mu1>
    <mu2>10.0</mu2>
    <material>Gazebo/Black</material>
  </gazebo>


  <joint name="joint_base_link_right_wheel" type="continuous">
    <origin rpy="0 0 0" xyz="0 -0.145 -0.07"/> <!-- axis flush with base at -0.0775 -->
    <parent link="base_link"/>
    <child link="right_wheel"/>
    <axis rpy="0 0 0" xyz="0 1 0"/>
    <limit effort="10000" velocity="1000"/>
    <joint_properties damping="1.0" friction="1.0"/>
  </joint>

    <!-- Casters -->
  <!-- Caster Wheel Front -->
  <link name="front_yaw_link">
      <visual>
        <origin rpy="0 1.5707 1.5707" xyz="0 0 0"/>
        <geometry>          
          <cylinder length="0.001" radius="0.0045000000000000005"/>
        </geometry>
        <material name="black"/>
      </visual>

      <collision>
        <origin rpy="0 1.5707 1.5707" xyz="0 0 0"/>
        <geometry>
          <cylinder length="0.001" radius="0.0045000000000000005"/>
        </geometry>
      </collision>

      <inertial>
          <origin rpy="0 1.5707 1.5707" xyz="0 0 0"/>
          <mass value="0.001"/>
          <inertia ixx="5.145833333333334e-09" ixy="0" ixz="0" iyy="5.145833333333334e-09" iyz="0" izz="1.0125000000000003e-08"/>
      </inertial>

  </link>

  <joint name="front_yaw_joint" type="continuous">
    <origin rpy="0 0 0" xyz="0.13 0 -0.0775" />
    <parent link="base_link" />
    <child link="front_yaw_link" />
    <axis xyz="0 0 1" />
    <limit effort="1000.0" velocity="100.0" />
    <dynamics damping="0.0" friction="0.1"/>
  </joint>

    <gazebo reference="front_yaw_link">
        <material>Gazebo/Black</material>
    </gazebo>

  <link name="front_roll_link">
      <visual>
        <origin rpy="0 1.5707 1.5707" xyz="0 0 0"/>
        <geometry>
          <cylinder length="0.001" radius="0.0045000000000000005"/>
        </geometry>
        <material name="black"/>
      </visual>

      <collision>
        <origin rpy="0 1.5707 1.5707" xyz="0 0 0"/>
        <geometry>
          <cylinder length="0.001" radius="0.0045000000000000005"/>
        </geometry>
      </collision>

      <inertial>
          <origin rpy="0 1.5707 1.5707" xyz="0 0 0"/>
          <mass value="0.001"/>
          <inertia ixx="5.145833333333334e-09" ixy="0" ixz="0" iyy="5.145833333333334e-09" iyz="0" izz="1.0125000000000003e-08"/>
      </inertial>
  </link>

  <joint name="front_roll_joint" type="continuous">
    <origin rpy="0 0 0" xyz="0 0 0" />
    <parent link="front_yaw_link" />
    <child link="front_roll_link" />
    <axis xyz="1 0 0" />
    <limit effort="1000.0" velocity="100.0" />
    <dynamics damping="0.0" friction="0.1"/>
  </joint>

    <gazebo reference="front_roll_link">
        <material>Gazebo/Black</material>
    </gazebo>


  <link name="front_pitch_link">
    <visual>
      <origin rpy="0 1.5707 1.5707" xyz="0 0 0"/>
      <geometry>
        <sphere radius="0.0325"/>
      </geometry>
      <material name="black"/>
    </visual>

    <collision>
      <origin rpy="0 1.5707 1.5707" xyz="0 0 0"/>
      <geometry>
        <sphere radius="0.0325"/>
      </geometry>
    </collision>

    <inertial>
        <origin rpy="0 1.5707 1.5707" xyz="0 0 0"/>
        <mass value="0.001"/>
        <inertia ixx="4e-08" ixy="0" ixz="0" iyy="4e-08" iyz="0" izz="4e-08"/>
    </inertial>
  </link>

  <gazebo reference="front_pitch_link">
    <kp>1000000000000000000000000000.0</kp>
    <kd>1000000000000000000000000000.0</kd>
    <mu1>0.5</mu1>
    <mu2>0.5</mu2>
    <material>Gazebo/Black</material>
  </gazebo>

  <joint name="front_pitch_joint" type="continuous">
    <origin rpy="0 0 0" xyz="0 0 0" />
    <parent link="front_roll_link" />
    <child link="front_pitch_link" />
    <axis xyz="0 1 0" />
    <limit effort="1000.0" velocity="100.0" />
    <dynamics damping="0.0" friction="0.1"/>
  </joint>

   <!-- Caster Wheel Back -->
  <link name="back_yaw_link">
      <visual>
        <origin rpy="0 1.5707 1.5707" xyz="0 0 0"/>
        <geometry>          
          <cylinder length="0.001" radius="0.0045000000000000005"/>
        </geometry>
        <material name="black"/>
      </visual>

      <collision>
        <origin rpy="0 1.5707 1.5707" xyz="0 0 0"/>
        <geometry>
          <cylinder length="0.001" radius="0.0045000000000000005"/>
        </geometry>
      </collision>

      <inertial>
          <origin rpy="0 1.5707 1.5707" xyz="0 0 0"/>
          <mass value="0.001"/>
          <inertia ixx="5.145833333333334e-09" ixy="0" ixz="0" iyy="5.145833333333334e-09" iyz="0" izz="1.0125000000000003e-08"/>
      </inertial>

  </link>

  <joint name="back_yaw_joint" type="continuous">
    <origin rpy="0 0 0" xyz="-0.13 0 -0.0775" />
    <parent link="base_link" />
    <child link="back_yaw_link" />
    <axis xyz="0 0 1" />
    <limit effort="1000.0" velocity="100.0" />
    <dynamics damping="0.0" friction="0.1"/>
  </joint>

    <gazebo reference="back_yaw_link">
        <material>Gazebo/Black</material>
    </gazebo>

  <link name="back_roll_link">
      <visual>
        <origin rpy="0 1.5707 1.5707" xyz="0 0 0"/>
        <geometry>
          <cylinder length="0.001" radius="0.0045000000000000005"/>
        </geometry>
        <material name="black"/>
      </visual>

      <collision>
        <origin rpy="0 1.5707 1.5707" xyz="0 0 0"/>
        <geometry>
          <cylinder length="0.001" radius="0.0045000000000000005"/>
        </geometry>
      </collision>

      <inertial>
          <origin rpy="0 1.5707 1.5707" xyz="0 0 0"/>
          <mass value="0.001"/>
          <inertia ixx="5.145833333333334e-09" ixy="0" ixz="0" iyy="5.145833333333334e-09" iyz="0" izz="1.0125000000000003e-08"/>
      </inertial>
  </link>

  <joint name="back_roll_joint" type="continuous">
    <origin rpy="0 0 0" xyz="0 0 0" />
    <parent link="back_yaw_link" />
    <child link="back_roll_link" />
    <axis xyz="1 0 0" />
    <limit effort="1000.0" velocity="100.0" />
    <dynamics damping="0.0" friction="0.1"/>
  </joint>

    <gazebo reference="back_roll_link">
        <material>Gazebo/Black</material>
    </gazebo>


  <link name="back_pitch_link">
    <visual>
      <origin rpy="0 1.5707 1.5707" xyz="0 0 0"/>
      <geometry>
        <sphere radius="0.0325"/>
      </geometry>
      <material name="black"/>
    </visual>

    <collision>
      <origin rpy="0 1.5707 1.5707" xyz="0 0 0"/>
      <geometry>
        <sphere radius="0.0325"/>
      </geometry>
    </collision>

    <inertial>
        <origin rpy="0 1.5707 1.5707" xyz="0 0 0"/>
        <mass value="0.001"/>
        <inertia ixx="4e-08" ixy="0" ixz="0" iyy="4e-08" iyz="0" izz="4e-08"/>
    </inertial>
  </link>

  <gazebo reference="back_pitch_link">
    <kp>1000000000000000000000000000.0</kp>
    <kd>1000000000000000000000000000.0</kd>
    <mu1>0.5</mu1>
    <mu2>0.5</mu2>
    <material>Gazebo/Black</material>
  </gazebo>

  <joint name="back_pitch_joint" type="continuous">
    <origin rpy="0 0 0" xyz="0 0 0" />
    <parent link="back_roll_link" />
    <child link="back_pitch_link" />
    <axis xyz="0 1 0" />
    <limit effort="1000.0" velocity="100.0" />
    <dynamics damping="0.0" friction="0.1"/>
  </joint>

   <!-- Laser sensor -->


</robot>