<sdf version='1.7'>
  <world name='default'>
    <light name='sun' type='directional'>
      <cast_shadows>1</cast_shadows>
      <pose>0 0 10 0 -0 0</pose>
      <diffuse>0.8 0.8 0.8 1</diffuse>
      <specular>0.2 0.2 0.2 1</specular>
      <attenuation>
        <range>1000</range>
        <constant>0.9</constant>
        <linear>0.01</linear>
        <quadratic>0.001</quadratic>
      </attenuation>
      <direction>-0.5 0.1 -0.9</direction>
      <spot>
        <inner_angle>0</inner_angle>
        <outer_angle>0</outer_angle>
        <falloff>0</falloff>
      </spot>
    </light>
    <model name='ground_plane'>
      <static>1</static>
      <link name='link'>
        <collision name='collision'>
          <geometry>
            <plane>
              <normal>0 0 1</normal>
              <size>100 100</size>
            </plane>
          </geometry>
          <surface>
            <contact>
              <collide_bitmask>65535</collide_bitmask>
              <ode/>
            </contact>
            <friction>
              <ode>
                <mu>100</mu>
                <mu2>50</mu2>
              </ode>
              <torsional>
                <ode/>
              </torsional>
            </friction>
            <bounce/>
          </surface>
          <max_contacts>10</max_contacts>
        </collision>
        <visual name='visual'>
          <cast_shadows>0</cast_shadows>
          <geometry>
            <plane>
              <normal>0 0 1</normal>
              <size>100 100</size>
            </plane>
          </geometry>
          <material>
            <script>
              <uri>file://media/materials/scripts/gazebo.material</uri>
              <name>Gazebo/Grey</name>
            </script>
          </material>
        </visual>
        <self_collide>0</self_collide>
        <enable_wind>0</enable_wind>
        <kinematic>0</kinematic>
      </link>
    </model>
    <gravity>0 0 -9.8</gravity>
    <magnetic_field>6e-06 2.3e-05 -4.2e-05</magnetic_field>
    <atmosphere type='adiabatic'/>
    <physics type='ode'>
      <max_step_size>0.001</max_step_size>
      <real_time_factor>1</real_time_factor>
      <real_time_update_rate>1000</real_time_update_rate>
    </physics>
    <scene>
      <ambient>0.4 0.4 0.4 1</ambient>
      <background>0.7 0.7 0.7 1</background>
      <shadows>1</shadows>
    </scene>
    <audio>
      <device>default</device>
    </audio>
    <wind/>
    <spherical_coordinates>
      <surface_model>EARTH_WGS84</surface_model>
      <latitude_deg>0</latitude_deg>
      <longitude_deg>0</longitude_deg>
      <elevation>0</elevation>
      <heading_deg>0</heading_deg>
    </spherical_coordinates>
    <model name='bar_bot-41796'>
      <link name='base_footprint'>
        <inertial>
          <pose>0.015072 0 0.061341 0 -0 0</pose>
          <mass>1.38</mass>
          <inertia>
            <ixx>0.031581</ixx>
            <ixy>0</ixy>
            <ixz>-0.000336116</ixz>
            <iyy>0.0338575</iyy>
            <iyz>0</iyz>
            <izz>0.0210065</izz>
          </inertia>
        </inertial>
        <collision name='base_footprint_fixed_joint_lump__base_link_collision'>
          <pose>0 0 0 0 -0 0</pose>
          <geometry>
            <cylinder>
              <length>0.155</length>
              <radius>0.178</radius>
            </cylinder>
          </geometry>
          <surface>
            <contact>
              <ode/>
            </contact>
            <friction>
              <ode/>
              <torsional>
                <ode/>
              </torsional>
            </friction>
            <bounce/>
          </surface>
          <max_contacts>10</max_contacts>
        </collision>
        <collision name='base_footprint_fixed_joint_lump__laser_scanner_collision_1'>
          <pose>0.13 0 0.0775 0 -0 0</pose>
          <geometry>
            <box>
              <size>0.05 0.05 0.07</size>
            </box>
          </geometry>
          <max_contacts>10</max_contacts>
          <surface>
            <contact>
              <ode/>
            </contact>
            <bounce/>
            <friction>
              <torsional>
                <ode/>
              </torsional>
              <ode/>
            </friction>
          </surface>
        </collision>
        <collision name='base_footprint_fixed_joint_lump__standoff_rods_collision_2'>
          <pose>0.05 0.14 0.1875 0 -0 0</pose>
          <geometry>
            <cylinder>
              <length>0.22</length>
              <radius>0.01</radius>
            </cylinder>
          </geometry>
          <max_contacts>10</max_contacts>
          <surface>
            <contact>
              <ode/>
            </contact>
            <bounce/>
            <friction>
              <torsional>
                <ode/>
              </torsional>
              <ode/>
            </friction>
          </surface>
        </collision>
        <collision name='base_footprint_fixed_joint_lump__standoff_rods_collision_3'>
          <pose>-0.05 0.14 0.1875 0 -0 0</pose>
          <geometry>
            <cylinder>
              <length>0.22</length>
              <radius>0.01</radius>
            </cylinder>
          </geometry>
          <max_contacts>10</max_contacts>
          <surface>
            <contact>
              <ode/>
            </contact>
            <bounce/>
            <friction>
              <torsional>
                <ode/>
              </torsional>
              <ode/>
            </friction>
          </surface>
        </collision>
        <collision name='base_footprint_fixed_joint_lump__standoff_rods_collision_4'>
          <pose>0.05 -0.14 0.1875 0 -0 0</pose>
          <geometry>
            <cylinder>
              <length>0.22</length>
              <radius>0.01</radius>
            </cylinder>
          </geometry>
          <max_contacts>10</max_contacts>
          <surface>
            <contact>
              <ode/>
            </contact>
            <bounce/>
            <friction>
              <torsional>
                <ode/>
              </torsional>
              <ode/>
            </friction>
          </surface>
        </collision>
        <collision name='base_footprint_fixed_joint_lump__standoff_rods_collision_5'>
          <pose>-0.05 -0.14 0.1875 0 -0 0</pose>
          <geometry>
            <cylinder>
              <length>0.22</length>
              <radius>0.01</radius>
            </cylinder>
          </geometry>
          <max_contacts>10</max_contacts>
          <surface>
            <contact>
              <ode/>
            </contact>
            <bounce/>
            <friction>
              <torsional>
                <ode/>
              </torsional>
              <ode/>
            </friction>
          </surface>
        </collision>
        <collision name='base_footprint_fixed_joint_lump__cup_holder_collision_6'>
          <pose>0 0 0.3425 0 -0 0</pose>
          <geometry>
            <cylinder>
              <length>0.09</length>
              <radius>0.16</radius>
            </cylinder>
          </geometry>
          <surface>
            <contact>
              <ode/>
            </contact>
            <friction>
              <ode/>
              <torsional>
                <ode/>
              </torsional>
            </friction>
            <bounce/>
          </surface>
          <max_contacts>10</max_contacts>
        </collision>
        <visual name='base_footprint_fixed_joint_lump__base_link_visual'>
          <pose>0 0 0 0 -0 0</pose>
          <geometry>
            <cylinder>
              <length>0.155</length>
              <radius>0.178</radius>
            </cylinder>
          </geometry>
          <material>
            <script>
              <name>Gazebo/Blue</name>
              <uri>file://media/materials/scripts/gazebo.material</uri>
            </script>
          </material>
        </visual>
        <visual name='base_footprint_fixed_joint_lump__laser_scanner_visual_1'>
          <pose>0.13 0 0.0775 0 -0 0</pose>
          <geometry>
            <mesh>
              <scale>1 1 1</scale>
              <uri>model://barista_robot_description/meshes/hokuyo_urg_04lx.dae</uri>
            </mesh>
          </geometry>
        </visual>
        <visual name='base_footprint_fixed_joint_lump__standoff_rods_visual_2'>
          <pose>0.05 0.14 0.1875 0 -0 0</pose>
          <geometry>
            <cylinder>
              <length>0.22</length>
              <radius>0.01</radius>
            </cylinder>
          </geometry>
        </visual>
        <visual name='base_footprint_fixed_joint_lump__standoff_rods_visual_3'>
          <pose>-0.05 0.14 0.1875 0 -0 0</pose>
          <geometry>
            <cylinder>
              <length>0.22</length>
              <radius>0.01</radius>
            </cylinder>
          </geometry>
        </visual>
        <visual name='base_footprint_fixed_joint_lump__standoff_rods_visual_4'>
          <pose>0.05 -0.14 0.1875 0 -0 0</pose>
          <geometry>
            <cylinder>
              <length>0.22</length>
              <radius>0.01</radius>
            </cylinder>
          </geometry>
        </visual>
        <visual name='base_footprint_fixed_joint_lump__standoff_rods_visual_5'>
          <pose>-0.05 -0.14 0.1875 0 -0 0</pose>
          <geometry>
            <cylinder>
              <length>0.22</length>
              <radius>0.01</radius>
            </cylinder>
          </geometry>
        </visual>
        <visual name='base_footprint_fixed_joint_lump__cup_holder_visual_6'>
          <pose>0 0 0.3425 0 -0 0</pose>
          <geometry>
            <cylinder>
              <length>0.09</length>
              <radius>0.16</radius>
            </cylinder>
          </geometry>
          <material>
            <script>
              <name>Gazebo/Blue</name>
              <uri>file://media/materials/scripts/gazebo.material</uri>
            </script>
          </material>
        </visual>
        <sensor name='sensor_ray' type='ray'>
          <ray>
            <scan>
              <horizontal>
                <samples>200</samples>
                <resolution>1</resolution>
                <min_angle>-3.14</min_angle>
                <max_angle>3.14</max_angle>
              </horizontal>
              <vertical>
                <samples>1</samples>
                <min_angle>0</min_angle>
                <max_angle>0</max_angle>
              </vertical>
            </scan>
            <range>
              <min>0.2</min>
              <max>5</max>
            </range>
          </ray>
          <always_on>1</always_on>
          <visualize>1</visualize>
          <update_rate>100</update_rate>
          <plugin name='laser' filename='libgazebo_ros_ray_sensor.so'>
            <ros>
              <namespace>/bar_bot</namespace>
              <remapping>~/out:=laser_scan</remapping>
            </ros>
            <output_type>sensor_msgs/LaserScan</output_type>
          </plugin>
          <pose>0.13 0 0.1075 0 -0 0</pose>
        </sensor>
        <self_collide>0</self_collide>
        <enable_wind>0</enable_wind>
        <kinematic>0</kinematic>
      </link>
      <joint name='back_yaw_joint' type='revolute'>
        <pose relative_to='base_footprint'>-0.13 0 -0.0775 0 -0 0</pose>
        <parent>base_footprint</parent>
        <child>back_yaw_link</child>
        <axis>
          <xyz>0 0 1</xyz>
          <limit>
            <effort>1000</effort>
            <velocity>100</velocity>
            <lower>-1e+16</lower>
            <upper>1e+16</upper>
          </limit>
          <dynamics>
            <damping>0</damping>
            <friction>0.1</friction>
            <spring_reference>0</spring_reference>
            <spring_stiffness>0</spring_stiffness>
          </dynamics>
        </axis>
      </joint>
      <link name='back_yaw_link'>
        <pose relative_to='back_yaw_joint'>0 0 0 0 -0 0</pose>
        <inertial>
          <pose>0 0 0 -0 1.5707 1.5707</pose>
          <mass>0.001</mass>
          <inertia>
            <ixx>5.14583e-09</ixx>
            <ixy>0</ixy>
            <ixz>0</ixz>
            <iyy>5.14583e-09</iyy>
            <iyz>0</iyz>
            <izz>1.0125e-08</izz>
          </inertia>
        </inertial>
        <collision name='back_yaw_link_collision'>
          <pose>0 0 0 1.57089 1.57079 -3.14159</pose>
          <geometry>
            <cylinder>
              <length>0.001</length>
              <radius>0.0045</radius>
            </cylinder>
          </geometry>
          <surface>
            <contact>
              <ode/>
            </contact>
            <friction>
              <ode/>
              <torsional>
                <ode/>
              </torsional>
            </friction>
            <bounce/>
          </surface>
          <max_contacts>10</max_contacts>
        </collision>
        <visual name='back_yaw_link_visual'>
          <pose>0 0 0 1.57089 1.57079 -3.14159</pose>
          <geometry>
            <cylinder>
              <length>0.001</length>
              <radius>0.0045</radius>
            </cylinder>
          </geometry>
          <material>
            <script>
              <name>Gazebo/Black</name>
              <uri>file://media/materials/scripts/gazebo.material</uri>
            </script>
          </material>
        </visual>
        <self_collide>0</self_collide>
        <enable_wind>0</enable_wind>
        <kinematic>0</kinematic>
      </link>
      <joint name='back_roll_joint' type='revolute'>
        <pose relative_to='back_yaw_link'>0 0 0 0 -0 0</pose>
        <parent>back_yaw_link</parent>
        <child>back_roll_link</child>
        <axis>
          <xyz>1 0 0</xyz>
          <limit>
            <effort>1000</effort>
            <velocity>100</velocity>
            <lower>-1e+16</lower>
            <upper>1e+16</upper>
          </limit>
          <dynamics>
            <damping>0</damping>
            <friction>0.1</friction>
            <spring_reference>0</spring_reference>
            <spring_stiffness>0</spring_stiffness>
          </dynamics>
        </axis>
      </joint>
      <link name='back_roll_link'>
        <pose relative_to='back_roll_joint'>0 0 0 0 -0 0</pose>
        <inertial>
          <pose>0 0 0 -0 1.5707 1.5707</pose>
          <mass>0.001</mass>
          <inertia>
            <ixx>5.14583e-09</ixx>
            <ixy>0</ixy>
            <ixz>0</ixz>
            <iyy>5.14583e-09</iyy>
            <iyz>0</iyz>
            <izz>1.0125e-08</izz>
          </inertia>
        </inertial>
        <collision name='back_roll_link_collision'>
          <pose>0 0 0 1.57089 1.57079 -3.14159</pose>
          <geometry>
            <cylinder>
              <length>0.001</length>
              <radius>0.0045</radius>
            </cylinder>
          </geometry>
          <surface>
            <contact>
              <ode/>
            </contact>
            <friction>
              <ode/>
              <torsional>
                <ode/>
              </torsional>
            </friction>
            <bounce/>
          </surface>
          <max_contacts>10</max_contacts>
        </collision>
        <visual name='back_roll_link_visual'>
          <pose>0 0 0 1.57089 1.57079 -3.14159</pose>
          <geometry>
            <cylinder>
              <length>0.001</length>
              <radius>0.0045</radius>
            </cylinder>
          </geometry>
          <material>
            <script>
              <name>Gazebo/Black</name>
              <uri>file://media/materials/scripts/gazebo.material</uri>
            </script>
          </material>
        </visual>
        <self_collide>0</self_collide>
        <enable_wind>0</enable_wind>
        <kinematic>0</kinematic>
      </link>
      <joint name='back_pitch_joint' type='revolute'>
        <pose relative_to='back_roll_link'>0 0 0 0 -0 0</pose>
        <parent>back_roll_link</parent>
        <child>back_pitch_link</child>
        <axis>
          <xyz>0 1 0</xyz>
          <limit>
            <effort>1000</effort>
            <velocity>100</velocity>
            <lower>-1e+16</lower>
            <upper>1e+16</upper>
          </limit>
          <dynamics>
            <damping>0</damping>
            <friction>0.1</friction>
            <spring_reference>0</spring_reference>
            <spring_stiffness>0</spring_stiffness>
          </dynamics>
        </axis>
      </joint>
      <link name='back_pitch_link'>
        <pose relative_to='back_pitch_joint'>0 0 0 0 -0 0</pose>
        <inertial>
          <pose>0 0 0 -0 1.5707 1.5707</pose>
          <mass>0.001</mass>
          <inertia>
            <ixx>4e-08</ixx>
            <ixy>0</ixy>
            <ixz>0</ixz>
            <iyy>4e-08</iyy>
            <iyz>0</iyz>
            <izz>4e-08</izz>
          </inertia>
        </inertial>
        <collision name='back_pitch_link_collision'>
          <pose>0 0 0 1.57089 1.57079 -3.14159</pose>
          <geometry>
            <sphere>
              <radius>0.0325</radius>
            </sphere>
          </geometry>
          <surface>
            <contact>
              <ode>
                <kp>1e+27</kp>
                <kd>1e+27</kd>
              </ode>
            </contact>
            <friction>
              <ode>
                <mu>0.5</mu>
                <mu2>0.5</mu2>
              </ode>
              <torsional>
                <ode/>
              </torsional>
            </friction>
            <bounce/>
          </surface>
          <max_contacts>10</max_contacts>
        </collision>
        <visual name='back_pitch_link_visual'>
          <pose>0 0 0 1.57089 1.57079 -3.14159</pose>
          <geometry>
            <sphere>
              <radius>0.0325</radius>
            </sphere>
          </geometry>
          <material>
            <script>
              <name>Gazebo/Black</name>
              <uri>file://media/materials/scripts/gazebo.material</uri>
            </script>
          </material>
        </visual>
        <self_collide>0</self_collide>
        <enable_wind>0</enable_wind>
        <kinematic>0</kinematic>
      </link>
      <joint name='front_yaw_joint' type='revolute'>
        <pose relative_to='base_footprint'>0.13 0 -0.0775 0 -0 0</pose>
        <parent>base_footprint</parent>
        <child>front_yaw_link</child>
        <axis>
          <xyz>0 0 1</xyz>
          <limit>
            <effort>1000</effort>
            <velocity>100</velocity>
            <lower>-1e+16</lower>
            <upper>1e+16</upper>
          </limit>
          <dynamics>
            <damping>0</damping>
            <friction>0.1</friction>
            <spring_reference>0</spring_reference>
            <spring_stiffness>0</spring_stiffness>
          </dynamics>
        </axis>
      </joint>
      <link name='front_yaw_link'>
        <pose relative_to='front_yaw_joint'>0 0 0 0 -0 0</pose>
        <inertial>
          <pose>0 0 0 -0 1.5707 1.5707</pose>
          <mass>0.001</mass>
          <inertia>
            <ixx>5.14583e-09</ixx>
            <ixy>0</ixy>
            <ixz>0</ixz>
            <iyy>5.14583e-09</iyy>
            <iyz>0</iyz>
            <izz>1.0125e-08</izz>
          </inertia>
        </inertial>
        <collision name='front_yaw_link_collision'>
          <pose>0 0 0 1.57089 1.57079 -3.14159</pose>
          <geometry>
            <cylinder>
              <length>0.001</length>
              <radius>0.0045</radius>
            </cylinder>
          </geometry>
          <surface>
            <contact>
              <ode/>
            </contact>
            <friction>
              <ode/>
              <torsional>
                <ode/>
              </torsional>
            </friction>
            <bounce/>
          </surface>
          <max_contacts>10</max_contacts>
        </collision>
        <visual name='front_yaw_link_visual'>
          <pose>0 0 0 1.57089 1.57079 -3.14159</pose>
          <geometry>
            <cylinder>
              <length>0.001</length>
              <radius>0.0045</radius>
            </cylinder>
          </geometry>
          <material>
            <script>
              <name>Gazebo/Black</name>
              <uri>file://media/materials/scripts/gazebo.material</uri>
            </script>
          </material>
        </visual>
        <self_collide>0</self_collide>
        <enable_wind>0</enable_wind>
        <kinematic>0</kinematic>
      </link>
      <joint name='front_roll_joint' type='revolute'>
        <pose relative_to='front_yaw_link'>0 0 0 0 -0 0</pose>
        <parent>front_yaw_link</parent>
        <child>front_roll_link</child>
        <axis>
          <xyz>1 0 0</xyz>
          <limit>
            <effort>1000</effort>
            <velocity>100</velocity>
            <lower>-1e+16</lower>
            <upper>1e+16</upper>
          </limit>
          <dynamics>
            <damping>0</damping>
            <friction>0.1</friction>
            <spring_reference>0</spring_reference>
            <spring_stiffness>0</spring_stiffness>
          </dynamics>
        </axis>
      </joint>
      <link name='front_roll_link'>
        <pose relative_to='front_roll_joint'>0 0 0 0 -0 0</pose>
        <inertial>
          <pose>0 0 0 -0 1.5707 1.5707</pose>
          <mass>0.001</mass>
          <inertia>
            <ixx>5.14583e-09</ixx>
            <ixy>0</ixy>
            <ixz>0</ixz>
            <iyy>5.14583e-09</iyy>
            <iyz>0</iyz>
            <izz>1.0125e-08</izz>
          </inertia>
        </inertial>
        <collision name='front_roll_link_collision'>
          <pose>0 0 0 1.57089 1.57079 -3.14159</pose>
          <geometry>
            <cylinder>
              <length>0.001</length>
              <radius>0.0045</radius>
            </cylinder>
          </geometry>
          <surface>
            <contact>
              <ode/>
            </contact>
            <friction>
              <ode/>
              <torsional>
                <ode/>
              </torsional>
            </friction>
            <bounce/>
          </surface>
          <max_contacts>10</max_contacts>
        </collision>
        <visual name='front_roll_link_visual'>
          <pose>0 0 0 1.57089 1.57079 -3.14159</pose>
          <geometry>
            <cylinder>
              <length>0.001</length>
              <radius>0.0045</radius>
            </cylinder>
          </geometry>
          <material>
            <script>
              <name>Gazebo/Black</name>
              <uri>file://media/materials/scripts/gazebo.material</uri>
            </script>
          </material>
        </visual>
        <self_collide>0</self_collide>
        <enable_wind>0</enable_wind>
        <kinematic>0</kinematic>
      </link>
      <joint name='front_pitch_joint' type='revolute'>
        <pose relative_to='front_roll_link'>0 0 0 0 -0 0</pose>
        <parent>front_roll_link</parent>
        <child>front_pitch_link</child>
        <axis>
          <xyz>0 1 0</xyz>
          <limit>
            <effort>1000</effort>
            <velocity>100</velocity>
            <lower>-1e+16</lower>
            <upper>1e+16</upper>
          </limit>
          <dynamics>
            <damping>0</damping>
            <friction>0.1</friction>
            <spring_reference>0</spring_reference>
            <spring_stiffness>0</spring_stiffness>
          </dynamics>
        </axis>
      </joint>
      <link name='front_pitch_link'>
        <pose relative_to='front_pitch_joint'>0 0 0 0 -0 0</pose>
        <inertial>
          <pose>0 0 0 -0 1.5707 1.5707</pose>
          <mass>0.001</mass>
          <inertia>
            <ixx>4e-08</ixx>
            <ixy>0</ixy>
            <ixz>0</ixz>
            <iyy>4e-08</iyy>
            <iyz>0</iyz>
            <izz>4e-08</izz>
          </inertia>
        </inertial>
        <collision name='front_pitch_link_collision'>
          <pose>0 0 0 1.57089 1.57079 -3.14159</pose>
          <geometry>
            <sphere>
              <radius>0.0325</radius>
            </sphere>
          </geometry>
          <surface>
            <contact>
              <ode>
                <kp>1e+27</kp>
                <kd>1e+27</kd>
              </ode>
            </contact>
            <friction>
              <ode>
                <mu>0.5</mu>
                <mu2>0.5</mu2>
              </ode>
              <torsional>
                <ode/>
              </torsional>
            </friction>
            <bounce/>
          </surface>
          <max_contacts>10</max_contacts>
        </collision>
        <visual name='front_pitch_link_visual'>
          <pose>0 0 0 1.57089 1.57079 -3.14159</pose>
          <geometry>
            <sphere>
              <radius>0.0325</radius>
            </sphere>
          </geometry>
          <material>
            <script>
              <name>Gazebo/Black</name>
              <uri>file://media/materials/scripts/gazebo.material</uri>
            </script>
          </material>
        </visual>
        <self_collide>0</self_collide>
        <enable_wind>0</enable_wind>
        <kinematic>0</kinematic>
      </link>
      <joint name='joint_base_link_left_wheel' type='revolute'>
        <pose relative_to='base_footprint'>0 0.145 -0.07 0 -0 0</pose>
        <parent>base_footprint</parent>
        <child>left_wheel</child>
        <axis>
          <xyz>0 1 0</xyz>
          <limit>
            <effort>10000</effort>
            <velocity>1000</velocity>
            <lower>-1e+16</lower>
            <upper>1e+16</upper>
          </limit>
          <dynamics>
            <spring_reference>0</spring_reference>
            <spring_stiffness>0</spring_stiffness>
          </dynamics>
        </axis>
      </joint>
      <link name='left_wheel'>
        <pose relative_to='joint_base_link_left_wheel'>0 0 0 0 -0 0</pose>
        <inertial>
          <pose>0 0 0 -0 1.5707 1.5707</pose>
          <mass>0.05</mass>
          <inertia>
            <ixx>1.53167e-05</ixx>
            <ixy>0</ixy>
            <ixz>0</ixz>
            <iyy>1.53167e-05</iyy>
            <iyz>0</iyz>
            <izz>3.0625e-05</izz>
          </inertia>
        </inertial>
        <collision name='left_wheel_collision'>
          <pose>0 0 0 1.57089 1.57079 -3.14159</pose>
          <geometry>
            <cylinder>
              <length>0.025</length>
              <radius>0.04</radius>
            </cylinder>
          </geometry>
          <surface>
            <contact>
              <ode>
                <kp>1e+27</kp>
                <kd>1e+27</kd>
              </ode>
            </contact>
            <friction>
              <ode>
                <mu>10</mu>
                <mu2>10</mu2>
              </ode>
              <torsional>
                <ode/>
              </torsional>
            </friction>
            <bounce/>
          </surface>
          <max_contacts>10</max_contacts>
        </collision>
        <visual name='left_wheel_visual'>
          <pose>0 0 0 1.57089 1.57079 -3.14159</pose>
          <geometry>
            <cylinder>
              <length>0.025</length>
              <radius>0.04</radius>
            </cylinder>
          </geometry>
          <material>
            <script>
              <name>Gazebo/Black</name>
              <uri>file://media/materials/scripts/gazebo.material</uri>
            </script>
          </material>
        </visual>
        <self_collide>0</self_collide>
        <enable_wind>0</enable_wind>
        <kinematic>0</kinematic>
      </link>
      <joint name='joint_base_link_right_wheel' type='revolute'>
        <pose relative_to='base_footprint'>0 -0.145 -0.07 0 -0 0</pose>
        <parent>base_footprint</parent>
        <child>right_wheel</child>
        <axis>
          <xyz>0 1 0</xyz>
          <limit>
            <effort>10000</effort>
            <velocity>1000</velocity>
            <lower>-1e+16</lower>
            <upper>1e+16</upper>
          </limit>
          <dynamics>
            <spring_reference>0</spring_reference>
            <spring_stiffness>0</spring_stiffness>
          </dynamics>
        </axis>
      </joint>
      <link name='right_wheel'>
        <pose relative_to='joint_base_link_right_wheel'>0 0 0 0 -0 0</pose>
        <inertial>
          <pose>0 0 0 -0 1.5707 1.5707</pose>
          <mass>0.05</mass>
          <inertia>
            <ixx>1.53167e-05</ixx>
            <ixy>0</ixy>
            <ixz>0</ixz>
            <iyy>1.53167e-05</iyy>
            <iyz>0</iyz>
            <izz>3.0625e-05</izz>
          </inertia>
        </inertial>
        <collision name='right_wheel_collision'>
          <pose>0 0 0 1.57089 1.57079 -3.14159</pose>
          <geometry>
            <cylinder>
              <length>0.025</length>
              <radius>0.04</radius>
            </cylinder>
          </geometry>
          <surface>
            <contact>
              <ode>
                <kp>1e+27</kp>
                <kd>1e+27</kd>
              </ode>
            </contact>
            <friction>
              <ode>
                <mu>10</mu>
                <mu2>10</mu2>
              </ode>
              <torsional>
                <ode/>
              </torsional>
            </friction>
            <bounce/>
          </surface>
          <max_contacts>10</max_contacts>
        </collision>
        <visual name='right_wheel_visual'>
          <pose>0 0 0 1.57089 1.57079 -3.14159</pose>
          <geometry>
            <cylinder>
              <length>0.025</length>
              <radius>0.04</radius>
            </cylinder>
          </geometry>
          <material>
            <script>
              <name>Gazebo/Black</name>
              <uri>file://media/materials/scripts/gazebo.material</uri>
            </script>
          </material>
        </visual>
        <self_collide>0</self_collide>
        <enable_wind>0</enable_wind>
        <kinematic>0</kinematic>
      </link>
      <plugin name='bar_bot_joint_state' filename='libgazebo_ros_joint_state_publisher.so'>
        <ros>
          <remapping>~/out:=joint_states</remapping>
        </ros>
        <update_rate>30</update_rate>
        <joint_name>joint_base_link_left_wheel</joint_name>
        <joint_name>joint_base_link_right_wheel</joint_name>
        <joint_name>front_yaw_joint</joint_name>
        <joint_name>back_yaw_joint</joint_name>
        <joint_name>front_roll_joint</joint_name>
        <joint_name>back_roll_joint</joint_name>
        <joint_name>front_pitch_joint</joint_name>
        <joint_name>back_pitch_joint</joint_name>
      </plugin>
      <static>0</static>
      <plugin name='differential_drive_controller' filename='libgazebo_ros_diff_drive.so'>
        <left_joint>joint_base_link_left_wheel</left_joint>
        <right_joint>joint_base_link_right_wheel</right_joint>
        <wheel_separation>0.29</wheel_separation>
        <wheel_diameter>0.08</wheel_diameter>
        <max_wheel_torque>1.0</max_wheel_torque>
        <max_wheel_acceleration>2.0</max_wheel_acceleration>
        <publish_odom>1</publish_odom>
        <publish_odom_tf>1</publish_odom_tf>
        <odometry_frame>odom</odometry_frame>
        <robot_base_frame>base_footprint</robot_base_frame>
      </plugin>
      <pose>0 0 0.11 0 -0 0</pose>
    </model>
    <model name='unit_box'>
      <pose>0.363599 -2.3466 0.5 0 -0 0</pose>
      <link name='link'>
        <inertial>
          <mass>1</mass>
          <inertia>
            <ixx>0.166667</ixx>
            <ixy>0</ixy>
            <ixz>0</ixz>
            <iyy>0.166667</iyy>
            <iyz>0</iyz>
            <izz>0.166667</izz>
          </inertia>
          <pose>0 0 0 0 -0 0</pose>
        </inertial>
        <collision name='collision'>
          <geometry>
            <box>
              <size>1 1 1</size>
            </box>
          </geometry>
          <max_contacts>10</max_contacts>
          <surface>
            <contact>
              <ode/>
            </contact>
            <bounce/>
            <friction>
              <torsional>
                <ode/>
              </torsional>
              <ode/>
            </friction>
          </surface>
        </collision>
        <visual name='visual'>
          <geometry>
            <box>
              <size>1 1 1</size>
            </box>
          </geometry>
          <material>
            <script>
              <name>Gazebo/Grey</name>
              <uri>file://media/materials/scripts/gazebo.material</uri>
            </script>
          </material>
        </visual>
        <self_collide>0</self_collide>
        <enable_wind>0</enable_wind>
        <kinematic>0</kinematic>
      </link>
    </model>
    <model name='unit_box_0'>
      <pose>2.11068 0.769465 0.5 0 -0 0</pose>
      <link name='link'>
        <inertial>
          <mass>1</mass>
          <inertia>
            <ixx>0.166667</ixx>
            <ixy>0</ixy>
            <ixz>0</ixz>
            <iyy>0.166667</iyy>
            <iyz>0</iyz>
            <izz>0.166667</izz>
          </inertia>
          <pose>0 0 0 0 -0 0</pose>
        </inertial>
        <collision name='collision'>
          <geometry>
            <box>
              <size>1 1 1</size>
            </box>
          </geometry>
          <max_contacts>10</max_contacts>
          <surface>
            <contact>
              <ode/>
            </contact>
            <bounce/>
            <friction>
              <torsional>
                <ode/>
              </torsional>
              <ode/>
            </friction>
          </surface>
        </collision>
        <visual name='visual'>
          <geometry>
            <box>
              <size>1 1 1</size>
            </box>
          </geometry>
          <material>
            <script>
              <name>Gazebo/Grey</name>
              <uri>file://media/materials/scripts/gazebo.material</uri>
            </script>
          </material>
        </visual>
        <self_collide>0</self_collide>
        <enable_wind>0</enable_wind>
        <kinematic>0</kinematic>
      </link>
    </model>
    <state world_name='default'>
      <sim_time>673 940000000</sim_time>
      <real_time>693 720351699</real_time>
      <wall_time>1721702185 979845280</wall_time>
      <iterations>673940</iterations>
      <model name='bar_bot-41796'>
        <pose>0.090752 0.00338 0.109995 -3e-06 0.001812 0.026214</pose>
        <scale>1 1 1</scale>
        <link name='back_pitch_link'>
          <pose>-0.039343 -3.1e-05 0.03273 0.04313 -0.048999 0.007268</pose>
          <velocity>0.000219 0.00024 0.000296 -6.5e-05 0.000628 -0.000175</velocity>
          <acceleration>0.044352 0.07436 0.164241 -1.83381 -0.558228 -0.193613</acceleration>
          <wrench>4.4e-05 7.4e-05 0.000164 0 -0 0</wrench>
        </link>
        <link name='back_roll_link'>
          <pose>-0.039343 -3.1e-05 0.03273 0.043079 0.001813 0.00946</pose>
          <velocity>0.00022 0.00023 0.000289 -0.000173 0.00071 -0.000174</velocity>
          <acceleration>0.043355 0.083569 0.171833 -1.92993 -0.554321 -0.16811</acceleration>
          <wrench>4.3e-05 8.4e-05 0.000172 0 -0 0</wrench>
        </link>
        <link name='back_yaw_link'>
          <pose>-0.039343 -3.1e-05 0.03273 -3.3e-05 0.001813 0.00946</pose>
          <velocity>0.00022 0.000228 0.000287 -7.4e-05 0.000708 -0.000168</velocity>
          <acceleration>0.044108 0.069759 0.167217 -1.79327 -0.577466 -0.19021</acceleration>
          <wrench>4.4e-05 7e-05 0.000167 0 -0 0</wrench>
        </link>
        <link name='base_footprint'>
          <pose>0.090752 0.00338 0.109995 -3e-06 0.001812 0.026214</pose>
          <velocity>0.000272 0.000227 0.000224 0.000297 0.000705 -0.000144</velocity>
          <acceleration>-0.036692 0.227754 0.234736 -1.36542 -0.602014 -0.211179</acceleration>
          <wrench>-0.050635 0.314301 0.323935 0 -0 0</wrench>
        </link>
        <link name='front_pitch_link'>
          <pose>0.220567 0.006784 0.032477 -2.76214 0.595219 -2.98363</pose>
          <velocity>0.000217 0.0002 0.006034 -0.006146 0.00658 -0.001215</velocity>
          <acceleration>0.044735 0.020125 0.130594 -0.620265 1.36364 0.01181</acceleration>
          <wrench>4.5e-05 2e-05 0.000131 0 -0 0</wrench>
        </link>
        <link name='front_roll_link'>
          <pose>0.220567 0.006784 0.032414 -0.311737 0.001851 -0.06261</pose>
          <velocity>0.000219 0.000192 0.004314 -0.005476 0.002687 -7.9e-05</velocity>
          <acceleration>0.044691 0.027991 0.178334 -1.09148 0.909255 0.285137</acceleration>
          <wrench>4.5e-05 2.8e-05 0.000178 0 -0 0</wrench>
        </link>
        <link name='front_yaw_link'>
          <pose>0.220567 0.006784 0.03235 -0.000173 0.00183 -0.062619</pose>
          <velocity>0.000219 0.000191 0.002596 -0.002684 0.001739 -0.000419</velocity>
          <acceleration>0.04558 0.015966 0.2326 -0.815884 0.177026 -0.205587</acceleration>
          <wrench>4.6e-05 1.6e-05 0.000233 0 -0 0</wrench>
        </link>
        <link name='left_wheel'>
          <pose>0.086825 0.148326 0.039996 -3.14092 1.18627 -3.11476</pose>
          <velocity>0.000219 0.000142 0.000648 -0.003024 0.004963 -0.001331</velocity>
          <acceleration>0.050497 0.111463 0.021441 -2.69725 0.84634 -1.10226</acceleration>
          <wrench>0.002525 0.005573 0.001072 0 -0 0</wrench>
        </link>
        <link name='right_wheel'>
          <pose>0.094426 -0.141574 0.039995 -3.14108 1.0789 -3.11489</pose>
          <velocity>0.000198 0.00036 -0.000345 -0.009009 0.004804 -0.00278</velocity>
          <acceleration>0.011186 0.391625 0.274974 -1.02244 -1.35143 0.170413</acceleration>
          <wrench>0.000559 0.019581 0.013749 0 -0 0</wrench>
        </link>
      </model>
      <model name='ground_plane'>
        <pose>0 0 0 0 -0 0</pose>
        <scale>1 1 1</scale>
        <link name='link'>
          <pose>0 0 0 0 -0 0</pose>
          <velocity>0 0 0 0 -0 0</velocity>
          <acceleration>0 0 0 0 -0 0</acceleration>
          <wrench>0 0 0 0 -0 0</wrench>
        </link>
      </model>
      <model name='unit_box'>
        <pose>0.363599 -2.3466 0.499995 -1e-05 -0 0</pose>
        <scale>1 1 1</scale>
        <link name='link'>
          <pose>0.363599 -2.3466 0.499995 -1e-05 -0 0</pose>
          <velocity>0 0 0 0 -0 0</velocity>
          <acceleration>0.004709 0.011055 -9.78158 -0.022108 0.009414 1e-06</acceleration>
          <wrench>0.004709 0.011055 -9.78158 0 -0 0</wrench>
        </link>
      </model>
      <model name='unit_box_0'>
        <pose>2.11068 0.769465 0.5 0 -0 0</pose>
        <scale>1 1 1</scale>
        <link name='link'>
          <pose>2.11068 0.769465 0.5 0 -0 0</pose>
          <velocity>0 0 0 0 -0 0</velocity>
          <acceleration>-0.004709 -9.78112 9.78158 0.712677 -0.009414 -4.3e-05</acceleration>
          <wrench>-0.004709 -9.78112 9.78158 0 -0 0</wrench>
        </link>
      </model>
      <light name='sun'>
        <pose>0 0 10 0 -0 0</pose>
      </light>
    </state>
    <gui fullscreen='0'>
      <camera name='user_camera'>
        <pose>5 -5 2 0 0.275643 2.35619</pose>
        <view_controller>orbit</view_controller>
        <projection_type>perspective</projection_type>
      </camera>
    </gui>
  </world>
</sdf>
